/home/pi/code/nice-rain-exercise-record/detection/distance.py:30: RuntimeWarning: This channel is already in use, continuing anyway.  Use GPIO.setwarnings(False) to disable warnings.
  GPIO.setup(TRIGGER_PIN, GPIO.OUT)
/home/pi/code/nice-rain-exercise-record/detection/distance.py:121: RuntimeWarning: This channel is already in use, continuing anyway.  Use GPIO.setwarnings(False) to disable warnings.
  GPIO.setup(BEEP_PIN, GPIO.OUT)
/home/pi/code/nice-rain-exercise-record/detection/distance.py:30: RuntimeWarning: This channel is already in use, continuing anyway.  Use GPIO.setwarnings(False) to disable warnings.
  GPIO.setup(TRIGGER_PIN, GPIO.OUT)
/home/pi/code/nice-rain-exercise-record/detection/distance.py:121: RuntimeWarning: This channel is already in use, continuing anyway.  Use GPIO.setwarnings(False) to disable warnings.
  GPIO.setup(BEEP_PIN, GPIO.OUT)
/home/pi/code/nice-rain-exercise-record/detection/distance.py:115: RuntimeWarning: This channel is already in use, continuing anyway.  Use GPIO.setwarnings(False) to disable warnings.
  GPIO.setup(BEEP_PIN, GPIO.OUT)
/home/pi/code/nice-rain-exercise-record/detection/distance.py:115: RuntimeWarning: This channel is already in use, continuing anyway.  Use GPIO.setwarnings(False) to disable warnings.
  GPIO.setup(BEEP_PIN, GPIO.OUT)
{'turns': 12, 'id': 19, 'time_stamp': '2023-07-11T15:14:45.716Z'}
count is  321
Traceback (most recent call last):
  File "/usr/lib/python3/dist-packages/urllib3/connection.py", line 169, in _new_conn
    conn = connection.create_connection(
  File "/usr/lib/python3/dist-packages/urllib3/util/connection.py", line 96, in create_connection
    raise err
  File "/usr/lib/python3/dist-packages/urllib3/util/connection.py", line 86, in create_connection
    sock.connect(sa)
ConnectionRefusedError: [Errno 111] Connection refused

During handling of the above exception, another exception occurred:

Traceback (most recent call last):
  File "/usr/lib/python3/dist-packages/urllib3/connectionpool.py", line 699, in urlopen
    httplib_response = self._make_request(
  File "/usr/lib/python3/dist-packages/urllib3/connectionpool.py", line 394, in _make_request
    conn.request(method, url, **httplib_request_kw)
  File "/usr/lib/python3/dist-packages/urllib3/connection.py", line 234, in request
    super(HTTPConnection, self).request(method, url, body=body, headers=headers)
  File "/usr/lib/python3.9/http/client.py", line 1255, in request
    self._send_request(method, url, body, headers, encode_chunked)
  File "/usr/lib/python3.9/http/client.py", line 1301, in _send_request
{'turns': 12, 'id': 20, 'time_stamp': '2023-07-11T15:18:56.180Z'}
count is  327
Traceback (most recent call last):
  File "/usr/lib/python3/dist-packages/urllib3/connection.py", line 169, in _new_conn
    self.endheaders(body, encode_chunked=encode_chunked)
  File "/usr/lib/python3.9/http/client.py", line 1250, in endheaders
    conn = connection.create_connection(
  File "/usr/lib/python3/dist-packages/urllib3/util/connection.py", line 96, in create_connection
    raise err
  File "/usr/lib/python3/dist-packages/urllib3/util/connection.py", line 86, in create_connection
    sock.connect(sa)
ConnectionRefusedError: [Errno 111] Connection refused

During handling of the above exception, another exception occurred:

Traceback (most recent call last):
  File "/usr/lib/python3/dist-packages/urllib3/connectionpool.py", line 699, in urlopen
    self._send_output(message_body, encode_chunked=encode_chunked)
  File "/usr/lib/python3.9/http/client.py", line 1010, in _send_output
    httplib_response = self._make_request(
  File "/usr/lib/python3/dist-packages/urllib3/connectionpool.py", line 394, in _make_request
    conn.request(method, url, **httplib_request_kw)
  File "/usr/lib/python3/dist-packages/urllib3/connection.py", line 234, in request
    self.send(msg)
  File "/usr/lib/python3.9/http/client.py", line 950, in send
    super(HTTPConnection, self).request(method, url, body=body, headers=headers)
  File "/usr/lib/python3.9/http/client.py", line 1255, in request
    self.connect()
  File "/usr/lib/python3/dist-packages/urllib3/connection.py", line 200, in connect
    self._send_request(method, url, body, headers, encode_chunked)
  File "/usr/lib/python3.9/http/client.py", line 1301, in _send_request
    conn = self._new_conn()
  File "/usr/lib/python3/dist-packages/urllib3/connection.py", line 181, in _new_conn
    raise NewConnectionError(
urllib3.exceptions.NewConnectionError: <urllib3.connection.HTTPConnection object at 0xf6c42100>: Failed to establish a new connection: [Errno 111] Connection refused

During handling of the above exception, another exception occurred:

Traceback (most recent call last):
  File "/usr/lib/python3/dist-packages/requests/adapters.py", line 439, in send
    resp = conn.urlopen(
  File "/usr/lib/python3/dist-packages/urllib3/connectionpool.py", line 755, in urlopen
    self.endheaders(body, encode_chunked=encode_chunked)
  File "/usr/lib/python3.9/http/client.py", line 1250, in endheaders
    retries = retries.increment(
  File "/usr/lib/python3/dist-packages/urllib3/util/retry.py", line 574, in increment
    raise MaxRetryError(_pool, url, error or ResponseError(cause))
    self._send_output(message_body, encode_chunked=encode_chunked)
urllib3.exceptions.MaxRetryError: HTTPConnectionPool(host='192.168.0.109', port=3000): Max retries exceeded with url: /nicerain (Caused by NewConnectionError('<urllib3.connection.HTTPConnection object at 0xf6c42100>: Failed to establish a new connection: [Errno 111] Connection refused'))
  File "/usr/lib/python3.9/http/client.py", line 1010, in _send_output

During handling of the above exception, another exception occurred:

Traceback (most recent call last):
  File "/home/pi/code/nice-rain-exercise-record/detection/distance.py", line 161, in <module>
    detection()
  File "/home/pi/code/nice-rain-exercise-record/detection/distance.py", line 123, in detection
    schedule.run_pending()
  File "/home/pi/.local/lib/python3.9/site-packages/schedule/__init__.py", line 822, in run_pending
    self.send(msg)
  File "/usr/lib/python3.9/http/client.py", line 950, in send
    default_scheduler.run_pending()
  File "/home/pi/.local/lib/python3.9/site-packages/schedule/__init__.py", line 100, in run_pending
    self._run_job(job)
  File "/home/pi/.local/lib/python3.9/site-packages/schedule/__init__.py", line 172, in _run_job
    self.connect()
  File "/usr/lib/python3/dist-packages/urllib3/connection.py", line 200, in connect
    ret = job.run()
    conn = self._new_conn()
  File "/home/pi/.local/lib/python3.9/site-packages/schedule/__init__.py", line 693, in run
  File "/usr/lib/python3/dist-packages/urllib3/connection.py", line 181, in _new_conn
    raise NewConnectionError(
urllib3.exceptions.NewConnectionError: <urllib3.connection.HTTPConnection object at 0xf6d50100>: Failed to establish a new connection: [Errno 111] Connection refused

During handling of the above exception, another exception occurred:

Traceback (most recent call last):
  File "/usr/lib/python3/dist-packages/requests/adapters.py", line 439, in send
    ret = self.job_func()
  File "/home/pi/code/nice-rain-exercise-record/detection/distance.py", line 153, in writeRecord
    resp = conn.urlopen(
  File "/usr/lib/python3/dist-packages/urllib3/connectionpool.py", line 755, in urlopen
    uploadTurns(countInAday)
  File "/home/pi/code/nice-rain-exercise-record/detection/distance.py", line 136, in uploadTurns
    res = requests.post(url='http://192.168.0.109:3000/nicerain',
  File "/usr/lib/python3/dist-packages/requests/api.py", line 119, in post
    return request('post', url, data=data, json=json, **kwargs)
  File "/usr/lib/python3/dist-packages/requests/api.py", line 61, in request
    retries = retries.increment(
  File "/usr/lib/python3/dist-packages/urllib3/util/retry.py", line 574, in increment
    return session.request(method=method, url=url, **kwargs)
  File "/usr/lib/python3/dist-packages/requests/sessions.py", line 542, in request
    raise MaxRetryError(_pool, url, error or ResponseError(cause))
urllib3.exceptions.MaxRetryError: HTTPConnectionPool(host='192.168.0.109', port=3000): Max retries exceeded with url: /nicerain (Caused by NewConnectionError('<urllib3.connection.HTTPConnection object at 0xf6d50100>: Failed to establish a new connection: [Errno 111] Connection refused'))

During handling of the above exception, another exception occurred:

Traceback (most recent call last):
  File "/home/pi/code/nice-rain-exercise-record/detection/distance.py", line 161, in <module>
    resp = self.send(prep, **send_kwargs)
  File "/usr/lib/python3/dist-packages/requests/sessions.py", line 655, in send
    detection()
  File "/home/pi/code/nice-rain-exercise-record/detection/distance.py", line 123, in detection
    schedule.run_pending()
  File "/home/pi/.local/lib/python3.9/site-packages/schedule/__init__.py", line 822, in run_pending
    r = adapter.send(request, **kwargs)
  File "/usr/lib/python3/dist-packages/requests/adapters.py", line 516, in send
    raise ConnectionError(e, request=request)
requests.exceptions.ConnectionError: HTTPConnectionPool(host='192.168.0.109', port=3000): Max retries exceeded with url: /nicerain (Caused by NewConnectionError('<urllib3.connection.HTTPConnection object at 0xf6c42100>: Failed to establish a new connection: [Errno 111] Connection refused'))
    default_scheduler.run_pending()
  File "/home/pi/.local/lib/python3.9/site-packages/schedule/__init__.py", line 100, in run_pending
    self._run_job(job)
  File "/home/pi/.local/lib/python3.9/site-packages/schedule/__init__.py", line 172, in _run_job
    ret = job.run()
  File "/home/pi/.local/lib/python3.9/site-packages/schedule/__init__.py", line 693, in run
    ret = self.job_func()
  File "/home/pi/code/nice-rain-exercise-record/detection/distance.py", line 153, in writeRecord
    uploadTurns(countInAday)
  File "/home/pi/code/nice-rain-exercise-record/detection/distance.py", line 136, in uploadTurns
    res = requests.post(url='http://192.168.0.109:3000/nicerain',
  File "/usr/lib/python3/dist-packages/requests/api.py", line 119, in post
    return request('post', url, data=data, json=json, **kwargs)
  File "/usr/lib/python3/dist-packages/requests/api.py", line 61, in request
    return session.request(method=method, url=url, **kwargs)
  File "/usr/lib/python3/dist-packages/requests/sessions.py", line 542, in request
    resp = self.send(prep, **send_kwargs)
  File "/usr/lib/python3/dist-packages/requests/sessions.py", line 655, in send
    r = adapter.send(request, **kwargs)
  File "/usr/lib/python3/dist-packages/requests/adapters.py", line 516, in send
    raise ConnectionError(e, request=request)
requests.exceptions.ConnectionError: HTTPConnectionPool(host='192.168.0.109', port=3000): Max retries exceeded with url: /nicerain (Caused by NewConnectionError('<urllib3.connection.HTTPConnection object at 0xf6d50100>: Failed to establish a new connection: [Errno 111] Connection refused'))
/home/pi/code/nice-rain-exercise-record/detection/distance.py:132: RuntimeWarning: No channels have been set up yet - nothing to clean up!  Try cleaning up at the end of your program instead!
  GPIO.cleanup()
[]
仓鼠一共跑了  0 圈
